Workbook

Sheet 견적데이터_정리
A1: MAC-BON 2025 표준 견적 데이터
A2: 제품 정보 | F2: 원가 · 표준판가 (개당) | J2: 등급별 판가 (kg당, 할인율 적용) | O2: 용기 | P2: 포장 옵션가 (원/개)
A3: 카테고리 | B3: 분류 | C3: 제품명 | D3: 충진 (g) | E3: 최소수량 (ea) | F3: 원가 (원/kg) | G3: 충원가 (원/개) | H3: 표준판가 (원/개) | I3: 마진율 | J3: D-C (0%) | K3: B (-10%) | L3: A (-15%) | M3: A+ (-20%) | N3: 20%할인 개당가 | O3: 용기구분 | P3: 용기 | Q3: 메탈캡 | R3: 파우치 | S3: 라벨 | T3: 단상자 | U3: 수축필름
A4: 일회용글루/리무버 | B4: 아크릴에멀젼 | C4: O-1201 / O-1211 / O-1301 / O-1311 | D4: =맥본_원가표!J9 -> 1 | E4: =맥본_원가표!P9 -> 10000 | F4: =맥본_원가표!I9 -> 25930 | G4: =맥본_원가표!O9 -> 141.5003 | H4: =맥본_원가표!Q9 -> 150 | I4: =맥본_원가표!R9 -> 0.056664667 | J4: =맥본_원가표!W9 -> 150000 | K4: =맥본_원가표!X9 -> 135000 | L4: =맥본_원가표!Y9 -> 127500 | M4: =맥본_원가표!Z9 -> 120000 | N4: =맥본_원가표!AA9 -> 120 | O4: =맥본_원가표!AC9 -> 용기포함 | P4: =맥본_원가표!AD9 -> - | Q4: =맥본_원가표!AE9 -> 300 | R4: =맥본_원가표!AF9 -> 150 | S4: =맥본_원가표!AG9 -> 50 | T4: =맥본_원가표!AH9 -> 100 | U4: =맥본_원가표!AI9 -> 200
D5: =맥본_원가표!J10 -> 3 | E5: =맥본_원가표!P10 -> 1000 | F5: =맥본_원가표!I9 -> 25930 | G5: =맥본_원가표!O10 -> 204.2509 | H5: =맥본_원가표!Q10 -> 400 | I5: =맥본_원가표!R10 -> 0.48937275 | J5: =맥본_원가표!W10 -> 133333.33 | K5: =맥본_원가표!X10 -> 120000 | L5: =맥본_원가표!Y10 -> 113333.33 | M5: =맥본_원가표!Z10 -> 106666.67 | N5: =맥본_원가표!AA10 -> 320 | O5: =맥본_원가표!AC10 -> 용기별도 | P5: =맥본_원가표!AD10 -> - | Q5: =맥본_원가표!AE10 -> 300 | R5: =맥본_원가표!AF10 -> 150 | S5: =맥본_원가표!AG10 -> 50 | T5: =맥본_원가표!AH10 -> 100 | U5: =맥본_원가표!AI10 -> 200
D6: =맥본_원가표!J11 -> 5 | E6: =맥본_원가표!P11 -> 1000 | F6: =맥본_원가표!I9 -> 25930 | G6: =맥본_원가표!O11 -> 267.0015 | H6: =맥본_원가표!Q11 -> 550 | I6: =맥본_원가표!R11 -> 0.51454273 | J6: =맥본_원가표!W11 -> 110000 | K6: =맥본_원가표!X11 -> 99000 | L6: =맥본_원가표!Y11 -> 93500 | M6: =맥본_원가표!Z11 -> 88000 | N6: =맥본_원가표!AA11 -> 440 | O6: =맥본_원가표!AC11 -> 용기별도 | P6: =맥본_원가표!AD11 -> - | Q6: =맥본_원가표!AE11 -> 300 | R6: =맥본_원가표!AF11 -> 150 | S6: =맥본_원가표!AG11 -> 50 | T6: =맥본_원가표!AH11 -> 100 | U6: =맥본_원가표!AI11 -> 200
D7: =맥본_원가표!J12 -> 7 | E7: =맥본_원가표!P12 -> 1000 | F7: =맥본_원가표!I9 -> 25930 | G7: =맥본_원가표!O12 -> 329.7521 | H7: =맥본_원가표!Q12 -> 700 | I7: =맥본_원가표!R12 -> 0.52892557 | J7: =맥본_원가표!W12 -> 100000 | K7: =맥본_원가표!X12 -> 90000 | L7: =맥본_원가표!Y12 -> 85000 | M7: =맥본_원가표!Z12 -> 80000 | N7: =맥본_원가표!AA12 -> 560 | O7: =맥본_원가표!AC12 -> 용기별도 | P7: =맥본_원가표!AD12 -> - | Q7: =맥본_원가표!AE12 -> 300 | R7: =맥본_원가표!AF12 -> 150 | S7: =맥본_원가표!AG12 -> 50 | T7: =맥본_원가표!AH12 -> 100 | U7: =맥본_원가표!AI12 -> 200
C8: O-1009 / O-1019 / O-1019FDA | D8: =맥본_원가표!J13 -> 1 | E8: =맥본_원가표!P13 -> 10000 | F8: =맥본_원가표!I13 -> 17906 | G8: =맥본_원가표!O13 -> 131.79126 | H8: =맥본_원가표!Q13 -> 150 | I8: =맥본_원가표!R13 -> 0.1213916 | J8: =맥본_원가표!W13 -> 150000 | K8: =맥본_원가표!X13 -> 135000 | L8: =맥본_원가표!Y13 -> 127500 | M8: =맥본_원가표!Z13 -> 120000 | N8: =맥본_원가표!AA13 -> 120 | O8: =맥본_원가표!AC13 -> 용기포함 | P8: =맥본_원가표!AD13 -> - | Q8: =맥본_원가표!AE13 -> 300 | R8: =맥본_원가표!AF13 -> 150 | S8: =맥본_원가표!AG13 -> 50 | T8: =맥본_원가표!AH13 -> 100 | U8: =맥본_원가표!AI13 -> 200
D9: =맥본_원가표!J14 -> 3 | E9: =맥본_원가표!P14 -> 1000 | F9: =맥본_원가표!I13 -> 17906 | G9: =맥본_원가표!O14 -> 175.12378 | H9: =맥본_원가표!Q14 -> 400 | I9: =맥본_원가표!R14 -> 0.56219055 | J9: =맥본_원가표!W14 -> 133333.33 | K9: =맥본_원가표!X14 -> 120000 | L9: =맥본_원가표!Y14 -> 113333.33 | M9: =맥본_원가표!Z14 -> 106666.67 | N9: =맥본_원가표!AA14 -> 320 | O9: =맥본_원가표!AC14 -> 용기별도 | P9: =맥본_원가표!AD14 -> - | Q9: =맥본_원가표!AE14 -> 300 | R9: =맥본_원가표!AF14 -> 150 | S9: =맥본_원가표!AG14 -> 50 | T9: =맥본_원가표!AH14 -> 100 | U9: =맥본_원가표!AI14 -> 200
D10: =맥본_원가표!J15 -> 5 | E10: =맥본_원가표!P15 -> 1000 | F10: =맥본_원가표!I13 -> 17906 | G10: =맥본_원가표!O15 -> 218.4563 | H10: =맥본_원가표!Q15 -> 550 | I10: =맥본_원가표!R15 -> 0.60280673 | J10: =맥본_원가표!W15 -> 110000 | K10: =맥본_원가표!X15 -> 99000 | L10: =맥본_원가표!Y15 -> 93500 | M10: =맥본_원가표!Z15 -> 88000 | N10: =맥본_원가표!AA15 -> 440 | O10: =맥본_원가표!AC15 -> 용기별도 | P10: =맥본_원가표!AD15 -> - | Q10: =맥본_원가표!AE15 -> 300 | R10: =맥본_원가표!AF15 -> 150 | S10: =맥본_원가표!AG15 -> 50 | T10: =맥본_원가표!AH15 -> 100 | U10: =맥본_원가표!AI15 -> 200
D11: =맥본_원가표!J16 -> 7 | E11: =맥본_원가표!P16 -> 1000 | F11: =맥본_원가표!I13 -> 17906 | G11: =맥본_원가표!O16 -> 261.78882 | H11: =맥본_원가표!Q16 -> 700 | I11: =맥본_원가표!R16 -> 0.62601597 | J11: =맥본_원가표!W16 -> 100000 | K11: =맥본_원가표!X16 -> 90000 | L11: =맥본_원가표!Y16 -> 85000 | M11: =맥본_원가표!Z16 -> 80000 | N11: =맥본_원가표!AA16 -> 560 | O11: =맥본_원가표!AC16 -> 용기별도 | P11: =맥본_원가표!AD16 -> - | Q11: =맥본_원가표!AE16 -> 300 | R11: =맥본_원가표!AF16 -> 150 | S11: =맥본_원가표!AG16 -> 50 | T11: =맥본_원가표!AH16 -> 100 | U11: =맥본_원가표!AI16 -> 200
B12: 아크릴리무버 | C12: U-303 | D12: =맥본_원가표!J17 -> 5 | E12: =맥본_원가표!P17 -> 1000 | F12: =맥본_원가표!I17 -> 46863.2 | G12: =맥본_원가표!O17 -> 459.72236 | H12: =맥본_원가표!Q17 -> 1200 | I12: =맥본_원가표!R17 -> 0.61689803 | J12: =맥본_원가표!W17 -> 240000 | K12: =맥본_원가표!X17 -> 216000 | L12: =맥본_원가표!Y17 -> 204000 | M12: =맥본_원가표!Z17 -> 192000 | N12: =맥본_원가표!AA17 -> 960 | O12: =맥본_원가표!AC17 -> 용기별도 | P12: =맥본_원가표!AD17 -> 550 | Q12: =맥본_원가표!AE17 -> 300 | R12: =맥본_원가표!AF17 -> 150 | S12: =맥본_원가표!AG17 -> 50 | T12: =맥본_원가표!AH17 -> 100 | U12: =맥본_원가표!AI17 -> 200
D13: =맥본_원가표!J18 -> 10 | E13: =맥본_원가표!P18 -> 1000 | F13: =맥본_원가표!I17 -> 46863.2 | G13: =맥본_원가표!O18 -> 743.24472 | H13: =맥본_원가표!Q18 -> 1500 | I13: =맥본_원가표!R18 -> 0.50450352 | J13: =맥본_원가표!W18 -> 150000 | K13: =맥본_원가표!X18 -> 135000 | L13: =맥본_원가표!Y18 -> 127500 | M13: =맥본_원가표!Z18 -> 120000 | N13: =맥본_원가표!AA18 -> 1200 | O13: =맥본_원가표!AC18 -> 용기별도 | P13: =맥본_원가표!AD18 -> 600 | Q13: =맥본_원가표!AE18 -> 300 | R13: =맥본_원가표!AF18 -> 150 | S13: =맥본_원가표!AG18 -> 50 | T13: =맥본_원가표!AH18 -> 100 | U13: =맥본_원가표!AI18 -> 200
C14: U-304 (제거력 강화) | D14: =맥본_원가표!J19 -> 5 | E14: =맥본_원가표!P19 -> 1000 | F14: =맥본_원가표!I19 -> 21800 | G14: =맥본_원가표!O19 -> 308.09 | H14: =맥본_원가표!Q19 -> 1100 | I14: =맥본_원가표!R19 -> 0.71991818 | J14: =맥본_원가표!W19 -> 220000 | K14: =맥본_원가표!X19 -> 198000 | L14: =맥본_원가표!Y19 -> 187000 | M14: =맥본_원가표!Z19 -> 176000 | N14: =맥본_원가표!AA19 -> 880 | O14: =맥본_원가표!AC19 -> 용기별도 | P14: =맥본_원가표!AD19 -> 550 | Q14: =맥본_원가표!AE19 -> 300 | R14: =맥본_원가표!AF19 -> 150 | S14: =맥본_원가표!AG19 -> 50 | T14: =맥본_원가표!AH19 -> 100 | U14: =맥본_원가표!AI19 -> 200
D15: =맥본_원가표!J20 -> 10 | E15: =맥본_원가표!P20 -> 1000 | F15: =맥본_원가표!I19 -> 21800 | G15: =맥본_원가표!O20 -> 439.98 | H15: =맥본_원가표!Q20 -> 1400 | I15: =맥본_원가표!R20 -> 0.68572857 | J15: =맥본_원가표!W20 -> 140000 | K15: =맥본_원가표!X20 -> 126000 | L15: =맥본_원가표!Y20 -> 119000 | M15: =맥본_원가표!Z20 -> 112000 | N15: =맥본_원가표!AA20 -> 1120 | O15: =맥본_원가표!AC20 -> 용기별도 | P15: =맥본_원가표!AD20 -> 600 | Q15: =맥본_원가표!AE20 -> 300 | R15: =맥본_원가표!AF20 -> 150 | S15: =맥본_원가표!AG20 -> 50 | T15: =맥본_원가표!AH20 -> 100 | U15: =맥본_원가표!AI20 -> 200
A16: 연장용글루 | B16: 글루 | C16: KC SERIES (초고순도 / MMA free, 전문가용) | D16: =맥본_원가표!J34 -> 3 | E16: =맥본_원가표!P34 -> 500 | F16: =맥본_원가표!I34 -> 83160 | G16: =맥본_원가표!O34 -> 566.1708 | H16: =맥본_원가표!Q34 -> 3500 | I16: =맥본_원가표!R34 -> 0.83823691 | J16: =맥본_원가표!W34 -> 1166666.7 | K16: =맥본_원가표!X34 -> 1050000 | L16: =맥본_원가표!Y34 -> 991666.67 | M16: =맥본_원가표!Z34 -> 933333.33 | N16: =맥본_원가표!AA34 -> 2800 | O16: =맥본_원가표!AC34 -> 용기포함 | P16: =맥본_원가표!AD34 -> - | Q16: =맥본_원가표!AE34 -> 300 | R16: =맥본_원가표!AF34 -> 150 | S16: =맥본_원가표!AG34 -> 50 | T16: =맥본_원가표!AH34 -> 100 | U16: =맥본_원가표!AI34 -> 200
D17: =맥본_원가표!J35 -> 5 | E17: =맥본_원가표!P35 -> 500 | F17: =맥본_원가표!I34 -> 83160 | G17: =맥본_원가표!O35 -> 767.418 | H17: =맥본_원가표!Q35 -> 4500 | I17: =맥본_원가표!R35 -> 0.82946267 | J17: =맥본_원가표!W35 -> 900000 | K17: =맥본_원가표!X35 -> 810000 | L17: =맥본_원가표!Y35 -> 765000 | M17: =맥본_원가표!Z35 -> 720000 | N17: =맥본_원가표!AA35 -> 3600 | O17: =맥본_원가표!AC35 -> 용기포함 | P17: =맥본_원가표!AD35 -> - | Q17: =맥본_원가표!AE35 -> 300 | R17: =맥본_원가표!AF35 -> 150 | S17: =맥본_원가표!AG35 -> 50 | T17: =맥본_원가표!AH35 -> 100 | U17: =맥본_원가표!AI35 -> 200
D18: =맥본_원가표!J36 -> 10 | E18: =맥본_원가표!P36 -> 500 | F18: =맥본_원가표!I34 -> 83160 | G18: =맥본_원가표!O36 -> 1270.536 | H18: =맥본_원가표!Q36 -> 7000 | I18: =맥본_원가표!R36 -> 0.81849486 | J18: =맥본_원가표!W36 -> 700000 | K18: =맥본_원가표!X36 -> 630000 | L18: =맥본_원가표!Y36 -> 595000 | M18: =맥본_원가표!Z36 -> 560000 | N18: =맥본_원가표!AA36 -> 5600 | O18: =맥본_원가표!AC36 -> 용기포함 | P18: =맥본_원가표!AD36 -> - | Q18: =맥본_원가표!AE36 -> 300 | R18: =맥본_원가표!AF36 -> 150 | S18: =맥본_원가표!AG36 -> 50 | T18: =맥본_원가표!AH36 -> 100 | U18: =맥본_원가표!AI36 -> 200
C19: KCB/T SERIES (저온저습 / MMA free, 전문가용) | D19: =맥본_원가표!J37 -> 3 | E19: =맥본_원가표!P37 -> 500 | F19: =맥본_원가표!I37 -> 116200 | G19: =맥본_원가표!O37 -> 686.106 | H19: =맥본_원가표!Q37 -> 3500 | I19: =맥본_원가표!R37 -> 0.80396971 | J19: =맥본_원가표!W37 -> 1166666.7 | K19: =맥본_원가표!X37 -> 1050000 | L19: =맥본_원가표!Y37 -> 991666.67 | M19: =맥본_원가표!Z37 -> 933333.33 | N19: =맥본_원가표!AA37 -> 2800 | O19: =맥본_원가표!AC37 -> 용기포함 | P19: =맥본_원가표!AD37 -> - | Q19: =맥본_원가표!AE37 -> 300 | R19: =맥본_원가표!AF37 -> 150 | S19: =맥본_원가표!AG37 -> 50 | T19: =맥본_원가표!AH37 -> 100 | U19: =맥본_원가표!AI37 -> 200
D20: =맥본_원가표!J38 -> 5 | E20: =맥본_원가표!P38 -> 500 | F20: =맥본_원가표!I37 -> 116200 | G20: =맥본_원가표!O38 -> 967.31 | H20: =맥본_원가표!Q38 -> 4500 | I20: =맥본_원가표!R38 -> 0.78504222 | J20: =맥본_원가표!W38 -> 900000 | K20: =맥본_원가표!X38 -> 810000 | L20: =맥본_원가표!Y38 -> 765000 | M20: =맥본_원가표!Z38 -> 720000 | N20: =맥본_원가표!AA38 -> 3600 | O20: =맥본_원가표!AC38 -> 용기포함 | P20: =맥본_원가표!AD38 -> - | Q20: =맥본_원가표!AE38 -> 300 | R20: =맥본_원가표!AF38 -> 150 | S20: =맥본_원가표!AG38 -> 50 | T20: =맥본_원가표!AH38 -> 100 | U20: =맥본_원가표!AI38 -> 200
D21: =맥본_원가표!J39 -> 10 | E21: =맥본_원가표!P39 -> 500 | F21: =맥본_원가표!I37 -> 116200 | G21: =맥본_원가표!O39 -> 1670.32 | H21: =맥본_원가표!Q39 -> 7000 | I21: =맥본_원가표!R39 -> 0.76138286 | J21: =맥본_원가표!W39 -> 700000 | K21: =맥본_원가표!X39 -> 630000 | L21: =맥본_원가표!Y39 -> 595000 | M21: =맥본_원가표!Z39 -> 560000 | N21: =맥본_원가표!AA39 -> 5600 | O21: =맥본_원가표!AC39 -> 용기포함 | P21: =맥본_원가표!AD39 -> - | Q21: =맥본_원가표!AE39 -> 300 | R21: =맥본_원가표!AF39 -> 150 | S21: =맥본_원가표!AG39 -> 50 | T21: =맥본_원가표!AH39 -> 100 | U21: =맥본_원가표!AI39 -> 200
C22: KC301 (초고순도 / MMA free / 셀프용, 무취, 저자극) | D22: =맥본_원가표!J40 -> 3 | E22: =맥본_원가표!P40 -> 500 | F22: =맥본_원가표!I40 -> 245303.8 | G22: =맥본_원가표!O40 -> 1154.7528 | H22: =맥본_원가표!Q40 -> 4500 | I22: =맥본_원가표!R40 -> 0.74338827 | J22: =맥본_원가표!W40 -> 1500000 | K22: =맥본_원가표!X40 -> 1350000 | L22: =맥본_원가표!Y40 -> 1275000 | M22: =맥본_원가표!Z40 -> 1200000 | N22: =맥본_원가표!AA40 -> 3600 | O22: =맥본_원가표!AC40 -> 용기포함 | P22: =맥본_원가표!AD40 -> - | Q22: =맥본_원가표!AE40 -> 300 | R22: =맥본_원가표!AF40 -> 150 | S22: =맥본_원가표!AG40 -> 50 | T22: =맥본_원가표!AH40 -> 100 | U22: =맥본_원가표!AI40 -> 200
D23: =맥본_원가표!J41 -> 5 | E23: =맥본_원가표!P41 -> 500 | F23: =맥본_원가표!I40 -> 245303.8 | G23: =맥본_원가표!O41 -> 1748.388 | H23: =맥본_원가표!Q41 -> 5500 | I23: =맥본_원가표!R41 -> 0.68211127 | J23: =맥본_원가표!W41 -> 1100000 | K23: =맥본_원가표!X41 -> 990000 | L23: =맥본_원가표!Y41 -> 935000 | M23: =맥본_원가표!Z41 -> 880000 | N23: =맥본_원가표!AA41 -> 4400 | O23: =맥본_원가표!AC41 -> 용기포함 | P23: =맥본_원가표!AD41 -> - | Q23: =맥본_원가표!AE41 -> 300 | R23: =맥본_원가표!AF41 -> 150 | S23: =맥본_원가표!AG41 -> 50 | T23: =맥본_원가표!AH41 -> 100 | U23: =맥본_원가표!AI41 -> 200
D24: =맥본_원가표!J42 -> 10 | E24: =맥본_원가표!P42 -> 500 | F24: =맥본_원가표!I40 -> 245303.8 | G24: =맥본_원가표!O42 -> 3232.476 | H24: =맥본_원가표!Q42 -> 8000 | I24: =맥본_원가표!R42 -> 0.5959405 | J24: =맥본_원가표!W42 -> 800000 | K24: =맥본_원가표!X42 -> 720000 | L24: =맥본_원가표!Y42 -> 680000 | M24: =맥본_원가표!Z42 -> 640000 | N24: =맥본_원가표!AA42 -> 6400 | O24: =맥본_원가표!AC42 -> 용기포함 | P24: =맥본_원가표!AD42 -> - | Q24: =맥본_원가표!AE42 -> 300 | R24: =맥본_원가표!AF42 -> 150 | S24: =맥본_원가표!AG42 -> 50 | T24: =맥본_원가표!AH42 -> 100 | U24: =맥본_원가표!AI42 -> 200
C25: TH SERIES (초고순도 / 저온저습) | D25: =맥본_원가표!J43 -> 3 | E25: =맥본_원가표!P43 -> 500 | F25: =맥본_원가표!I43 -> 70416 | G25: =맥본_원가표!O43 -> 519.91008 | H25: =맥본_원가표!Q43 -> 1600 | I25: =맥본_원가표!R43 -> 0.6750562 | J25: =맥본_원가표!W43 -> 533333.33 | K25: =맥본_원가표!X43 -> 480000 | L25: =맥본_원가표!Y43 -> 453333.33 | M25: =맥본_원가표!Z43 -> 426666.67 | N25: =맥본_원가표!AA43 -> 1280 | O25: =맥본_원가표!AC43 -> 용기포함 | P25: =맥본_원가표!AD43 -> - | Q25: =맥본_원가표!AE43 -> 300 | R25: =맥본_원가표!AF43 -> 150 | S25: =맥본_원가표!AG43 -> 50 | T25: =맥본_원가표!AH43 -> 100 | U25: =맥본_원가표!AI43 -> 200
D26: =맥본_원가표!J44 -> 5 | E26: =맥본_원가표!P44 -> 500 | F26: =맥본_원가표!I43 -> 70416 | G26: =맥본_원가표!O44 -> 690.3168 | H26: =맥본_원가표!Q44 -> 2000 | I26: =맥본_원가표!R44 -> 0.6548416 | J26: =맥본_원가표!W44 -> 400000 | K26: =맥본_원가표!X44 -> 360000 | L26: =맥본_원가표!Y44 -> 340000 | M26: =맥본_원가표!Z44 -> 320000 | N26: =맥본_원가표!AA44 -> 1600 | O26: =맥본_원가표!AC44 -> 용기포함 | P26: =맥본_원가표!AD44 -> - | Q26: =맥본_원가표!AE44 -> 300 | R26: =맥본_원가표!AF44 -> 150 | S26: =맥본_원가표!AG44 -> 50 | T26: =맥본_원가표!AH44 -> 100 | U26: =맥본_원가표!AI44 -> 200
D27: =맥본_원가표!J45 -> 10 | E27: =맥본_원가표!P45 -> 500 | F27: =맥본_원가표!I43 -> 70416 | G27: =맥본_원가표!O45 -> 1116.3336 | H27: =맥본_원가표!Q45 -> 3000 | I27: =맥본_원가표!R45 -> 0.6278888 | J27: =맥본_원가표!W45 -> 300000 | K27: =맥본_원가표!X45 -> 270000 | L27: =맥본_원가표!Y45 -> 255000 | M27: =맥본_원가표!Z45 -> 240000 | N27: =맥본_원가표!AA45 -> 2400 | O27: =맥본_원가표!AC45 -> 용기포함 | P27: =맥본_원가표!AD45 -> - | Q27: =맥본_원가표!AE45 -> 300 | R27: =맥본_원가표!AF45 -> 150 | S27: =맥본_원가표!AG45 -> 50 | T27: =맥본_원가표!AH45 -> 100 | U27: =맥본_원가표!AI45 -> 200
C28: CM SERIES (초고순도 / 유연성) | D28: =맥본_원가표!J46 -> 3 | E28: =맥본_원가표!P46 -> 500 | F28: =맥본_원가표!I46 -> 86346 | G28: =맥본_원가표!O46 -> 577.73598 | H28: =맥본_원가표!Q46 -> 1400 | I28: =맥본_원가표!R46 -> 0.58733144 | J28: =맥본_원가표!W46 -> 466666.67 | K28: =맥본_원가표!X46 -> 420000 | L28: =맥본_원가표!Y46 -> 396666.67 | M28: =맥본_원가표!Z46 -> 373333.33 | N28: =맥본_원가표!AA46 -> 1120 | O28: =맥본_원가표!AC46 -> 용기포함 | P28: =맥본_원가표!AD46 -> - | Q28: =맥본_원가표!AE46 -> 300 | R28: =맥본_원가표!AF46 -> 150 | S28: =맥본_원가표!AG46 -> 50 | T28: =맥본_원가표!AH46 -> 100 | U28: =맥본_원가표!AI46 -> 200
D29: =맥본_원가표!J47 -> 5 | E29: =맥본_원가표!P47 -> 500 | F29: =맥본_원가표!I46 -> 86346 | G29: =맥본_원가표!O47 -> 786.6933 | H29: =맥본_원가표!Q47 -> 1800 | I29: =맥본_원가표!R47 -> 0.56294817 | J29: =맥본_원가표!W47 -> 360000 | K29: =맥본_원가표!X47 -> 324000 | L29: =맥본_원가표!Y47 -> 306000 | M29: =맥본_원가표!Z47 -> 288000 | N29: =맥본_원가표!AA47 -> 1440 | O29: =맥본_원가표!AC47 -> 용기포함 | P29: =맥본_원가표!AD47 -> - | Q29: =맥본_원가표!AE47 -> 300 | R29: =맥본_원가표!AF47 -> 150 | S29: =맥본_원가표!AG47 -> 50 | T29: =맥본_원가표!AH47 -> 100 | U29: =맥본_원가표!AI47 -> 200
D30: =맥본_원가표!J48 -> 10 | E30: =맥본_원가표!P48 -> 500 | F30: =맥본_원가표!I46 -> 86346 | G30: =맥본_원가표!O48 -> 1309.0866 | H30: =맥본_원가표!Q48 -> 2800 | I30: =맥본_원가표!R48 -> 0.53246907 | J30: =맥본_원가표!W48 -> 280000 | K30: =맥본_원가표!X48 -> 252000 | L30: =맥본_원가표!Y48 -> 238000 | M30: =맥본_원가표!Z48 -> 224000 | N30: =맥본_원가표!AA48 -> 2240 | O30: =맥본_원가표!AC48 -> 용기포함 | P30: =맥본_원가표!AD48 -> - | Q30: =맥본_원가표!AE48 -> 300 | R30: =맥본_원가표!AF48 -> 150 | S30: =맥본_원가표!AG48 -> 50 | T30: =맥본_원가표!AH48 -> 100 | U30: =맥본_원가표!AI48 -> 200
C31: S SERIES (고순도 / 빠른경화) | D31: =맥본_원가표!J49 -> 3 | E31: =맥본_원가표!P49 -> 500 | F31: =맥본_원가표!I49 -> 61920 | G31: =맥본_원가표!O49 -> 489.0696 | H31: =맥본_원가표!Q49 -> 1200 | I31: =맥본_원가표!R49 -> 0.592442 | J31: =맥본_원가표!W49 -> 400000 | K31: =맥본_원가표!X49 -> 360000 | L31: =맥본_원가표!Y49 -> 340000 | M31: =맥본_원가표!Z49 -> 320000 | N31: =맥본_원가표!AA49 -> 960 | O31: =맥본_원가표!AC49 -> 용기포함 | P31: =맥본_원가표!AD49 -> - | Q31: =맥본_원가표!AE49 -> 300 | R31: =맥본_원가표!AF49 -> 150 | S31: =맥본_원가표!AG49 -> 50 | T31: =맥본_원가표!AH49 -> 100 | U31: =맥본_원가표!AI49 -> 200
D32: =맥본_원가표!J50 -> 5 | E32: =맥본_원가표!P50 -> 500 | F32: =맥본_원가표!I49 -> 61920 | G32: =맥본_원가표!O50 -> 638.916 | H32: =맥본_원가표!Q50 -> 1600 | I32: =맥본_원가표!R50 -> 0.6006775 | J32: =맥본_원가표!W50 -> 320000 | K32: =맥본_원가표!X50 -> 288000 | L32: =맥본_원가표!Y50 -> 272000 | M32: =맥본_원가표!Z50 -> 256000 | N32: =맥본_원가표!AA50 -> 1280 | O32: =맥본_원가표!AC50 -> 용기포함 | P32: =맥본_원가표!AD50 -> - | Q32: =맥본_원가표!AE50 -> 300 | R32: =맥본_원가표!AF50 -> 150 | S32: =맥본_원가표!AG50 -> 50 | T32: =맥본_원가표!AH50 -> 100 | U32: =맥본_원가표!AI50 -> 200
D33: =맥본_원가표!J51 -> 10 | E33: =맥본_원가표!P51 -> 500 | F33: =맥본_원가표!I49 -> 61920 | G33: =맥본_원가표!O51 -> 1013.532 | H33: =맥본_원가표!Q51 -> 2600 | I33: =맥본_원가표!R51 -> 0.61018 | J33: =맥본_원가표!W51 -> 260000 | K33: =맥본_원가표!X51 -> 234000 | L33: =맥본_원가표!Y51 -> 221000 | M33: =맥본_원가표!Z51 -> 208000 | N33: =맥본_원가표!AA51 -> 2080 | O33: =맥본_원가표!AC51 -> 용기포함 | P33: =맥본_원가표!AD51 -> - | Q33: =맥본_원가표!AE51 -> 300 | R33: =맥본_원가표!AF51 -> 150 | S33: =맥본_원가표!AG51 -> 50 | T33: =맥본_원가표!AH51 -> 100 | U33: =맥본_원가표!AI51 -> 200
C34: E SERIES (보급형) | D34: =맥본_원가표!J52 -> 3 | E34: =맥본_원가표!P52 -> 500 | F34: =맥본_원가표!I52 -> 51654 | G34: =맥본_원가표!O52 -> 451.80402 | H34: =맥본_원가표!Q52 -> 1100 | I34: =맥본_원가표!R52 -> 0.58926907 | J34: =맥본_원가표!W52 -> 366666.67 | K34: =맥본_원가표!X52 -> 330000 | L34: =맥본_원가표!Y52 -> 311666.67 | M34: =맥본_원가표!Z52 -> 293333.33 | N34: =맥본_원가표!AA52 -> 880 | O34: =맥본_원가표!AC52 -> 용기포함 | P34: =맥본_원가표!AD52 -> - | Q34: =맥본_원가표!AE52 -> 300 | R34: =맥본_원가표!AF52 -> 150 | S34: =맥본_원가표!AG52 -> 50 | T34: =맥본_원가표!AH52 -> 100 | U34: =맥본_원가표!AI52 -> 200
D35: =맥본_원가표!J53 -> 5 | E35: =맥본_원가표!P53 -> 500 | F35: =맥본_원가표!I52 -> 51654 | G35: =맥본_원가표!O53 -> 576.8067 | H35: =맥본_원가표!Q53 -> 1400 | I35: =맥본_원가표!R53 -> 0.58799521 | J35: =맥본_원가표!W53 -> 280000 | K35: =맥본_원가표!X53 -> 252000 | L35: =맥본_원가표!Y53 -> 238000 | M35: =맥본_원가표!Z53 -> 224000 | N35: =맥본_원가표!AA53 -> 1120 | O35: =맥본_원가표!AC53 -> 용기포함 | P35: =맥본_원가표!AD53 -> - | Q35: =맥본_원가표!AE53 -> 300 | R35: =맥본_원가표!AF53 -> 150 | S35: =맥본_원가표!AG53 -> 50 | T35: =맥본_원가표!AH53 -> 100 | U35: =맥본_원가표!AI53 -> 200
D36: =맥본_원가표!J54 -> 10 | E36: =맥본_원가표!P54 -> 500 | F36: =맥본_원가표!I52 -> 51654 | G36: =맥본_원가표!O54 -> 889.3134 | H36: =맥본_원가표!Q54 -> 2400 | I36: =맥본_원가표!R54 -> 0.62945275 | J36: =맥본_원가표!W54 -> 240000 | K36: =맥본_원가표!X54 -> 216000 | L36: =맥본_원가표!Y54 -> 204000 | M36: =맥본_원가표!Z54 -> 192000 | N36: =맥본_원가표!AA54 -> 1920 | O36: =맥본_원가표!AC54 -> 용기포함 | P36: =맥본_원가표!AD54 -> - | Q36: =맥본_원가표!AE54 -> 300 | R36: =맥본_원가표!AF54 -> 150 | S36: =맥본_원가표!AG54 -> 50 | T36: =맥본_원가표!AH54 -> 100 | U36: =맥본_원가표!AI54 -> 200
C37: K158-R9 (PMMA, 무취, 저자극) | D37: =맥본_원가표!J55 -> 3 | E37: =맥본_원가표!P55 -> 500 | F37: =맥본_원가표!I55 -> 104400 | G37: =맥본_원가표!O55 -> 643.272 | H37: =맥본_원가표!Q55 -> 1800 | I37: =맥본_원가표!R55 -> 0.64262667 | J37: =맥본_원가표!W55 -> 600000 | K37: =맥본_원가표!X55 -> 540000 | L37: =맥본_원가표!Y55 -> 510000 | M37: =맥본_원가표!Z55 -> 480000 | N37: =맥본_원가표!AA55 -> 1440 | O37: =맥본_원가표!AC55 -> 용기포함 | P37: =맥본_원가표!AD55 -> - | Q37: =맥본_원가표!AE55 -> 300 | R37: =맥본_원가표!AF55 -> 150 | S37: =맥본_원가표!AG55 -> 50 | T37: =맥본_원가표!AH55 -> 100 | U37: =맥본_원가표!AI55 -> 200
D38: =맥본_원가표!J56 -> 5 | E38: =맥본_원가표!P56 -> 500 | F38: =맥본_원가표!I55 -> 104400 | G38: =맥본_원가표!O56 -> 895.92 | H38: =맥본_원가표!Q56 -> 2300 | I38: =맥본_원가표!R56 -> 0.61046957 | J38: =맥본_원가표!W56 -> 460000 | K38: =맥본_원가표!X56 -> 414000 | L38: =맥본_원가표!Y56 -> 391000 | M38: =맥본_원가표!Z56 -> 368000 | N38: =맥본_원가표!AA56 -> 1840 | O38: =맥본_원가표!AC56 -> 용기포함 | P38: =맥본_원가표!AD56 -> - | Q38: =맥본_원가표!AE56 -> 300 | R38: =맥본_원가표!AF56 -> 150 | S38: =맥본_원가표!AG56 -> 50 | T38: =맥본_원가표!AH56 -> 100 | U38: =맥본_원가표!AI56 -> 200
D39: =맥본_원가표!J57 -> 10 | E39: =맥본_원가표!P57 -> 500 | F39: =맥본_원가표!I55 -> 104400 | G39: =맥본_원가표!O57 -> 1527.54 | H39: =맥본_원가표!Q57 -> 3600 | I39: =맥본_원가표!R57 -> 0.57568333 | J39: =맥본_원가표!W57 -> 360000 | K39: =맥본_원가표!X57 -> 324000 | L39: =맥본_원가표!Y57 -> 306000 | M39: =맥본_원가표!Z57 -> 288000 | N39: =맥본_원가표!AA57 -> 2880 | O39: =맥본_원가표!AC57 -> 용기포함 | P39: =맥본_원가표!AD57 -> - | Q39: =맥본_원가표!AE57 -> 300 | R39: =맥본_원가표!AF57 -> 150 | S39: =맥본_원가표!AG57 -> 50 | T39: =맥본_원가표!AH57 -> 100 | U39: =맥본_원가표!AI57 -> 200
A40: 리무버 | B40: 리무버 | C40: GBL REMOVER K25 / K26 / K27 / R145 (겔, 크림) | D40: =맥본_원가표!J63 -> 5 | E40: =맥본_원가표!P63 -> 1000 | F40: =맥본_원가표!I63 -> 20000 | G40: =맥본_원가표!O63 -> 385.3 | H40: =맥본_원가표!Q63 -> 1000 | I40: =맥본_원가표!R63 -> 0.6147 | J40: =맥본_원가표!W63 -> 200000 | K40: =맥본_원가표!X63 -> 180000 | L40: =맥본_원가표!Y63 -> 170000 | M40: =맥본_원가표!Z63 -> 160000 | N40: =맥본_원가표!AA63 -> 800 | O40: =맥본_원가표!AC63 -> 용기별도 | P40: =맥본_원가표!AD63 -> 200 | Q40: =맥본_원가표!AE63 -> 300 | R40: =맥본_원가표!AF63 -> 150 | S40: =맥본_원가표!AG63 -> 50 | T40: =맥본_원가표!AH63 -> 100 | U40: =맥본_원가표!AI63 -> 200
...

Sheet 맥본_원가표
B4: MB 전제품 표준견적서 [일회용글루/리무버]
M5: 1000개 작업시 표준공임 | Q5: 제품가 | U5: 참고용 | W5: 업체등급별 할인율(kg당) | AD5: 포장사양 (옵션가)
B6: 제품분류 | C6: 제품명 | D6: 규격 | E6: 공장출하가 (RMB) | F6: 운임 (RMB) | G6: 관부가세 (RMB) | H6: 원가 (RMB) | I6: 원가 (KRW) | J6: 충진규격 (g) | K6: 원가비(A) | L6: 공수(초) | M6: 공임(B) | N6: 관리비(C) | O6: 충원가(D) | P6: 최소수량 (ea) | Q6: 표준판가 (E) | R6: 마진율 | S6: 한국표준판가 (kg당) | T6: 평균표준판가 (kg당) | U6: 중국표준판가 (kg당) | W6: D-C | X6: B | Y6: A | Z6: A+ | AA6: A+ | AB6: 마진율 (20%할인시) | AC6: 비고 | AD6: 용기 | AE6: 메탈캡 | AF6: 파우치 | AG6: 라벨포장 | AH6: 단상자포장 | AI6: 수축필름
K7: 로스율 | L7: 임률(원) | M7: 충진+캡핑+마킹 | N7: (A+B)*10% | O7: (A+B+C) | Q7: 최소수량기준 | R7: (E-D)/E | W7: 할인율 | X7: 할인율 | Y7: 할인율 | Z7: 할인율 | AA7: 할인율
G8: 0.18 | K8: 0.1 | L8: 80 | W8: 0 | X8: 0.1 | Y8: 0.15 | Z8: 0.2 | AA8: 0.2
B9: 아크릴 에멀젼 | C9: O-1201 / O-1211 / O-1301 / O-1311 | D9: 1kg | E9: 67.5 | F9: 50 | G9: =E9*$G$8 -> 12.15 | H9: =SUM(E9:G9) -> 129.65 | I9: =H9*200 -> 25930 | J9: 1 | K9: =I9/1000*J9*(1+$K$8) -> 28.523 | L9: 1.25 | M9: =$L$8*L9 -> 100 | N9: =SUM(K9:M9)*0.1 -> 12.9773 | O9: =SUM(K9+M9+N9) -> 141.5003 | P9: 10000 | Q9: 150 | R9: =(Q9-O9)/Q9 -> 0.056664667 | S9: =Q9/J9*1000 -> 150000 | U9: 70000 | W9: =S9*(1-$W$8) -> 150000 | X9: =S9*(1-$X$8) -> 135000 | Y9: =S9*(1-$Y$8) -> 127500 | Z9: =S9*(1-$Z$8) -> 120000 | AA9: =Q9*(1-$AA$8) -> 120 | AB9: =(AA9-O9)/AA9 -> -0.17916917 | AC9: 용기포함 | AD9: - | AE9: 300 | AF9: 150 | AG9: 50 | AH9: 100 | AI9: 200
J10: 3 | K10: =I9/1000*J10*(1+$K$8) -> 85.569 | L10: 1.25 | M10: =$L$8*L10 -> 100 | N10: =SUM(K10:M10)*0.1 -> 18.6819 | O10: =SUM(K10+M10+N10) -> 204.2509 | P10: 1000 | Q10: 400 | R10: =(Q10-O10)/Q10 -> 0.48937275 | S10: =Q10/J10*1000 -> 133333.33 | W10: =S10*(1-$W$8) -> 133333.33 | X10: =S10*(1-$X$8) -> 120000 | Y10: =S10*(1-$Y$8) -> 113333.33 | Z10: =S10*(1-$Z$8) -> 106666.67 | AA10: =Q10*(1-$AA$8) -> 320 | AB10: =(AA10-O10)/AA10 -> 0.36171594 | AC10: 용기별도 | AD10: - | AE10: 300 | AF10: 150 | AG10: 50 | AH10: 100 | AI10: 200
J11: 5 | K11: =I9/1000*J11*(1+$K$8) -> 142.615 | L11: 1.25 | M11: =$L$8*L11 -> 100 | N11: =SUM(K11:M11)*0.1 -> 24.3865 | O11: =SUM(K11+M11+N11) -> 267.0015 | P11: 1000 | Q11: 550 | R11: =(Q11-O11)/Q11 -> 0.51454273 | S11: =Q11/J11*1000 -> 110000 | W11: =S11*(1-$W$8) -> 110000 | X11: =S11*(1-$X$8) -> 99000 | Y11: =S11*(1-$Y$8) -> 93500 | Z11: =S11*(1-$Z$8) -> 88000 | AA11: =Q11*(1-$AA$8) -> 440 | AB11: =(AA11-O11)/AA11 -> 0.39317841 | AC11: 용기별도 | AD11: - | AE11: 300 | AF11: 150 | AG11: 50 | AH11: 100 | AI11: 200
J12: 7 | K12: =I9/1000*J12*(1+$K$8) -> 199.661 | L12: 1.25 | M12: =$L$8*L12 -> 100 | N12: =SUM(K12:M12)*0.1 -> 30.0911 | O12: =SUM(K12+M12+N12) -> 329.7521 | P12: 1000 | Q12: 700 | R12: =(Q12-O12)/Q12 -> 0.52892557 | S12: =Q12/J12*1000 -> 100000 | W12: =S12*(1-$W$8) -> 100000 | X12: =S12*(1-$X$8) -> 90000 | Y12: =S12*(1-$Y$8) -> 85000 | Z12: =S12*(1-$Z$8) -> 80000 | AA12: =Q12*(1-$AA$8) -> 560 | AB12: =(AA12-O12)/AA12 -> 0.41115696 | AC12: 용기별도 | AD12: - | AE12: 300 | AF12: 150 | AG12: 50 | AH12: 100 | AI12: 200
C13: O-1009 / O-1019 / O-1019FDA | D13: 1kg | E13: 33.5 | F13: 50 | G13: =E13*$G$8 -> 6.03 | H13: =SUM(E13:G13) -> 89.53 | I13: =H13*200 -> 17906 | J13: 1 | K13: =I13/1000*J13*(1+$K$8) -> 19.6966 | L13: 1.25 | M13: =$L$8*L13 -> 100 | N13: =SUM(K13:M13)*0.1 -> 12.09466 | O13: =SUM(K13+M13+N13) -> 131.79126 | P13: 10000 | Q13: 150 | R13: =(Q13-O13)/Q13 -> 0.1213916 | S13: =Q13/J13*1000 -> 150000 | U13: 70000 | W13: =S13*(1-$W$8) -> 150000 | X13: =S13*(1-$X$8) -> 135000 | Y13: =S13*(1-$Y$8) -> 127500 | Z13: =S13*(1-$Z$8) -> 120000 | AA13: =Q13*(1-$AA$8) -> 120 | AB13: =(AA13-O13)/AA13 -> -0.0982605 | AC13: 용기포함 | AD13: - | AE13: 300 | AF13: 150 | AG13: 50 | AH13: 100 | AI13: 200
J14: 3 | K14: =I13/1000*J14*(1+$K$8) -> 59.0898 | L14: 1.25 | M14: =$L$8*L14 -> 100 | N14: =SUM(K14:M14)*0.1 -> 16.03398 | O14: =SUM(K14+M14+N14) -> 175.12378 | P14: 1000 | Q14: 400 | R14: =(Q14-O14)/Q14 -> 0.56219055 | S14: =Q14/J14*1000 -> 133333.33 | W14: =S14*(1-$W$8) -> 133333.33 | X14: =S14*(1-$X$8) -> 120000 | Y14: =S14*(1-$Y$8) -> 113333.33 | Z14: =S14*(1-$Z$8) -> 106666.67 | AA14: =Q14*(1-$AA$8) -> 320 | AB14: =(AA14-O14)/AA14 -> 0.45273819 | AC14: 용기별도 | AD14: - | AE14: 300 | AF14: 150 | AG14: 50 | AH14: 100 | AI14: 200
J15: 5 | K15: =I13/1000*J15*(1+$K$8) -> 98.483 | L15: 1.25 | M15: =$L$8*L15 -> 100 | N15: =SUM(K15:M15)*0.1 -> 19.9733 | O15: =SUM(K15+M15+N15) -> 218.4563 | P15: 1000 | Q15: 550 | R15: =(Q15-O15)/Q15 -> 0.60280673 | S15: =Q15/J15*1000 -> 110000 | W15: =S15*(1-$W$8) -> 110000 | X15: =S15*(1-$X$8) -> 99000 | Y15: =S15*(1-$Y$8) -> 93500 | Z15: =S15*(1-$Z$8) -> 88000 | AA15: =Q15*(1-$AA$8) -> 440 | AB15: =(AA15-O15)/AA15 -> 0.50350841 | AC15: 용기별도 | AD15: - | AE15: 300 | AF15: 150 | AG15: 50 | AH15: 100 | AI15: 200
J16: 7 | K16: =I13/1000*J16*(1+$K$8) -> 137.8762 | L16: 1.25 | M16: =$L$8*L16 -> 100 | N16: =SUM(K16:M16)*0.1 -> 23.91262 | O16: =SUM(K16+M16+N16) -> 261.78882 | P16: 1000 | Q16: 700 | R16: =(Q16-O16)/Q16 -> 0.62601597 | S16: =Q16/J16*1000 -> 100000 | W16: =S16*(1-$W$8) -> 100000 | X16: =S16*(1-$X$8) -> 90000 | Y16: =S16*(1-$Y$8) -> 85000 | Z16: =S16*(1-$Z$8) -> 80000 | AA16: =Q16*(1-$AA$8) -> 560 | AB16: =(AA16-O16)/AA16 -> 0.53251996 | AC16: 용기별도 | AD16: - | AE16: 300 | AF16: 150 | AG16: 50 | AH16: 100 | AI16: 200
B17: 아크릴 리무버 | C17: U-303 | D17: 1kg | E17: 156.2 | F17: 50 | G17: =E17*$G$8 -> 28.116 | H17: =SUM(E17:G17) -> 234.316 | I17: =H17*200 -> 46863.2 | J17: 5 | K17: =I17/1000*J17*(1+$K$8) -> 257.7476 | L17: 2 | M17: =$L$8*L17 -> 160 | N17: =SUM(K17:M17)*0.1 -> 41.97476 | O17: =SUM(K17+M17+N17) -> 459.72236 | P17: 1000 | Q17: 1200 | R17: =(Q17-O17)/Q17 -> 0.61689803 | S17: =Q17/J17*1000 -> 240000 | U17: 200000 | W17: =S17*(1-$W$8) -> 240000 | X17: =S17*(1-$X$8) -> 216000 | Y17: =S17*(1-$Y$8) -> 204000 | Z17: =S17*(1-$Z$8) -> 192000 | AA17: =Q17*(1-$AA$8) -> 960 | AB17: =(AA17-O17)/AA17 -> 0.52112254 | AC17: 용기별도 | AD17: 550 | AE17: 300 | AF17: 150 | AG17: 50 | AH17: 100 | AI17: 200
J18: 10 | K18: =I17/1000*J18*(1+$K$8) -> 515.4952 | L18: 2 | M18: =$L$8*L18 -> 160 | N18: =SUM(K18:M18)*0.1 -> 67.74952 | O18: =SUM(K18+M18+N18) -> 743.24472 | P18: 1000 | Q18: 1500 | R18: =(Q18-O18)/Q18 -> 0.50450352 | S18: =Q18/J18*1000 -> 150000 | W18: =S18*(1-$W$8) -> 150000 | X18: =S18*(1-$X$8) -> 135000 | Y18: =S18*(1-$Y$8) -> 127500 | Z18: =S18*(1-$Z$8) -> 120000 | AA18: =Q18*(1-$AA$8) -> 1200 | AB18: =(AA18-O18)/AA18 -> 0.3806294 | AC18: 용기별도 | AD18: 600 | AE18: 300 | AF18: 150 | AG18: 50 | AH18: 100 | AI18: 200
C19: U-304 (제거력 강화) | D19: 1kg | E19: 50 | F19: 50 | G19: =E19*$G$8 -> 9 | H19: =SUM(E19:G19) -> 109 | I19: =H19*200 -> 21800 | J19: 5 | K19: =I19/1000*J19*(1+$K$8) -> 119.9 | L19: 2 | M19: =$L$8*L19 -> 160 | N19: =SUM(K19:M19)*0.1 -> 28.19 | O19: =SUM(K19+M19+N19) -> 308.09 | P19: 1000 | Q19: 1100 | R19: =(Q19-O19)/Q19 -> 0.71991818 | S19: =Q19/J19*1000 -> 220000 | U19: 160000 | W19: =S19*(1-$W$8) -> 220000 | X19: =S19*(1-$X$8) -> 198000 | Y19: =S19*(1-$Y$8) -> 187000 | Z19: =S19*(1-$Z$8) -> 176000 | AA19: =Q19*(1-$AA$8) -> 880 | AB19: =(AA19-O19)/AA19 -> 0.64989773 | AC19: 용기별도 | AD19: 550 | AE19: 300 | AF19: 150 | AG19: 50 | AH19: 100 | AI19: 200
J20: 10 | K20: =I19/1000*J20*(1+$K$8) -> 239.8 | L20: 2 | M20: =$L$8*L20 -> 160 | N20: =SUM(K20:M20)*0.1 -> 40.18 | O20: =SUM(K20+M20+N20) -> 439.98 | P20: 1000 | Q20: 1400 | R20: =(Q20-O20)/Q20 -> 0.68572857 | S20: =Q20/J20*1000 -> 140000 | W20: =S20*(1-$W$8) -> 140000 | X20: =S20*(1-$X$8) -> 126000 | Y20: =S20*(1-$Y$8) -> 119000 | Z20: =S20*(1-$Z$8) -> 112000 | AA20: =Q20*(1-$AA$8) -> 1120 | AB20: =(AA20-O20)/AA20 -> 0.60716071 | AC20: 용기별도 | AD20: 600 | AE20: 300 | AF20: 150 | AG20: 50 | AH20: 100 | AI20: 200
B29: MB 전제품 표준견적서 [연장용글루]
M30: 1000개 작업시 표준공임 | Q30: 제품가 | U30: 참고용 | W30: 업체등급별 할인율(kg당) | AD30: 포장사양 (옵션가)
B31: 제품분류 | C31: 제품명 | D31: 규격 | E31: 공장출하가 (RMB) | F31: 운임 (RMB) | G31: 관부가세 (RMB) | H31: 원가 (RMB) | I31: 원가 (KRW) | J31: 충진규격 (g) | K31: 원가비(A) | L31: 공수(초) | M31: 공임(B) | N31: 관리비(C) | O31: 충원가(D) | P31: 최소수량 (ea) | Q31: 표준판가 (E) | R31: 마진율 | S31: 한국표준판가 (kg당) | T31: 평균표준판가 (kg당) | U31: 중국표준판가 (kg당) | W31: D-C | X31: B | Y31: A | Z31: A+ | AA31: A+ | AB31: 마진율 (20%할인시) | AC31: 비고 | AD31: 용기 | AE31: 메탈캡 | AF31: 파우치 | AG31: 라벨포장 | AH31: 단상자포장 | AI31: 수축필름
K32: 로스율 | L32: 임률(원) | M32: 충진+캡핑+마킹 | N32: (A+B)*10% | O32: (A+B+C) | Q32: 최소수량기준 | R32: (E-D)/E | W32: 할인율 | X32: 할인율 | Y32: 할인율 | Z32: 할인율 | AA32: 할인율
G33: 0.18 | K33: 0.1 | L33: 80 | W33: 0 | X33: 0.1 | Y33: 0.15 | Z33: 0.2 | AA33: 0.2
B34: 글루 | C34: KC SERIES (초고순도 / MMA free, 전문가용) | D34: 1kg | E34: 310 | F34: 50 | G34: =E34*$G$8 -> 55.8 | H34: =SUM(E34:G34) -> 415.8 | I34: =H34*200 -> 83160 | J34: 3 | K34: =I34/1000*J34*(1+$K$8) -> 274.428 | L34: 3 | M34: =$L$8*L34 -> 240 | N34: =SUM(K34:M34)*0.1 -> 51.7428 | O34: =SUM(K34+M34+N34) -> 566.1708 | P34: 500 | Q34: 3500 | R34: =(Q34-O34)/Q34 -> 0.83823691 | S34: =Q34/J34*1000 -> 1166666.7 | U34: 400000 | W34: =S34*(1-$W$8) -> 1166666.7 | X34: =S34*(1-$X$8) -> 1050000 | Y34: =S34*(1-$Y$8) -> 991666.67 | Z34: =S34*(1-$Z$8) -> 933333.33 | AA34: =Q34*(1-$AA$8) -> 2800 | AB34: =(AA34-O34)/AA34 -> 0.79779614 | AC34: 용기포함 | AD34: - | AE34: 300 | AF34: 150 | AG34: 50 | AH34: 100 | AI34: 200
J35: 5 | K35: =I34/1000*J35*(1+$K$8) -> 457.38 | L35: 3 | M35: =$L$8*L35 -> 240 | N35: =SUM(K35:M35)*0.1 -> 70.038 | O35: =SUM(K35+M35+N35) -> 767.418 | P35: 500 | Q35: 4500 | R35: =(Q35-O35)/Q35 -> 0.82946267 | S35: =Q35/J35*1000 -> 900000 | W35: =S35*(1-$W$8) -> 900000 | X35: =S35*(1-$X$8) -> 810000 | Y35: =S35*(1-$Y$8) -> 765000 | Z35: =S35*(1-$Z$8) -> 720000 | AA35: =Q35*(1-$AA$8) -> 3600 | AB35: =(AA35-O35)/AA35 -> 0.78682833 | AC35: 용기포함 | AD35: - | AE35: 300 | AF35: 150 | AG35: 50 | AH35: 100 | AI35: 200
J36: 10 | K36: =I34/1000*J36*(1+$K$8) -> 914.76 | L36: 3 | M36: =$L$8*L36 -> 240 | N36: =SUM(K36:M36)*0.1 -> 115.776 | O36: =SUM(K36+M36+N36) -> 1270.536 | P36: 500 | Q36: 7000 | R36: =(Q36-O36)/Q36 -> 0.81849486 | S36: =Q36/J36*1000 -> 700000 | W36: =S36*(1-$W$8) -> 700000 | X36: =S36*(1-$X$8) -> 630000 | Y36: =S36*(1-$Y$8) -> 595000 | Z36: =S36*(1-$Z$8) -> 560000 | AA36: =Q36*(1-$AA$8) -> 5600 | AB36: =(AA36-O36)/AA36 -> 0.77311857 | AC36: 용기포함 | AD36: - | AE36: 300 | AF36: 150 | AG36: 50 | AH36: 100 | AI36: 200
C37: KCB/T SERIES (저온저습 / MMA free, 전문가용) | D37: 1kg | E37: 450 | F37: 50 | G37: =E37*$G$8 -> 81 | H37: =SUM(E37:G37) -> 581 | I37: =H37*200 -> 116200 | J37: 3 | K37: =I37/1000*J37*(1+$K$8) -> 383.46 | L37: 3 | M37: =$L$8*L37 -> 240 | N37: =SUM(K37:M37)*0.1 -> 62.646 | O37: =SUM(K37+M37+N37) -> 686.106 | P37: 500 | Q37: 3500 | R37: =(Q37-O37)/Q37 -> 0.80396971 | S37: =Q37/J37*1000 -> 1166666.7 | U37: 400000 | W37: =S37*(1-$W$8) -> 1166666.7 | X37: =S37*(1-$X$8) -> 1050000 | Y37: =S37*(1-$Y$8) -> 991666.67 | Z37: =S37*(1-$Z$8) -> 933333.33 | AA37: =Q37*(1-$AA$8) -> 2800 | AB37: =(AA37-O37)/AA37 -> 0.75496214 | AC37: 용기포함 | AD37: - | AE37: 300 | AF37: 150 | AG37: 50 | AH37: 100 | AI37: 200
J38: 5 | K38: =I37/1000*J38*(1+$K$8) -> 639.1 | L38: 3 | M38: =$L$8*L38 -> 240 | N38: =SUM(K38:M38)*0.1 -> 88.21 | O38: =SUM(K38+M38+N38) -> 967.31 | P38: 500 | Q38: 4500 | R38: =(Q38-O38)/Q38 -> 0.78504222 | S38: =Q38/J38*1000 -> 900000 | W38: =S38*(1-$W$8) -> 900000 | X38: =S38*(1-$X$8) -> 810000 | Y38: =S38*(1-$Y$8) -> 765000 | Z38: =S38*(1-$Z$8) -> 720000 | AA38: =Q38*(1-$AA$8) -> 3600 | AB38: =(AA38-O38)/AA38 -> 0.73130278 | AC38: 용기포함 | AD38: - | AE38: 300 | AF38: 150 | AG38: 50 | AH38: 100 | AI38: 200
J39: 10 | K39: =I37/1000*J39*(1+$K$8) -> 1278.2 | L39: 3 | M39: =$L$8*L39 -> 240 | N39: =SUM(K39:M39)*0.1 -> 152.12 | O39: =SUM(K39+M39+N39) -> 1670.32 | P39: 500 | Q39: 7000 | R39: =(Q39-O39)/Q39 -> 0.76138286 | S39: =Q39/J39*1000 -> 700000 | W39: =S39*(1-$W$8) -> 700000 | X39: =S39*(1-$X$8) -> 630000 | Y39: =S39*(1-$Y$8) -> 595000 | Z39: =S39*(1-$Z$8) -> 560000 | AA39: =Q39*(1-$AA$8) -> 5600 | AB39: =(AA39-O39)/AA39 -> 0.70172857 | AC39: 용기포함 | AD39: - | AE39: 300 | AF39: 150 | AG39: 50 | AH39: 100 | AI39: 200
C40: KC301 (초고순도 / MMA free / 셀프용, 무취, 저자극) | D40: 1kg | E40: 997.05 | F40: 50 | G40: =E40*$G$8 -> 179.469 | H40: =SUM(E40:G40) -> 1226.519 | I40: =H40*200 -> 245303.8 | J40: 3 | K40: =I40/1000*J40*(1+$K$8) -> 809.50254 | L40: 3 | M40: =$L$8*L40 -> 240 | N40: =SUM(K40:M40)*0.1 -> 105.25025 | O40: =SUM(K40+M40+N40) -> 1154.7528 | P40: 500 | Q40: 4500 | R40: =(Q40-O40)/Q40 -> 0.74338827 | S40: =Q40/J40*1000 -> 1500000 | U40: 1000000 | W40: =S40*(1-$W$8) -> 1500000 | X40: =S40*(1-$X$8) -> 1350000 | Y40: =S40*(1-$Y$8) -> 1275000 | Z40: =S40*(1-$Z$8) -> 1200000 | AA40: =Q40*(1-$AA$8) -> 3600 | AB40: =(AA40-O40)/AA40 -> 0.67923533 | AC40: 용기포함 | AD40: - | AE40: 300 | AF40: 150 | AG40: 50 | AH40: 100 | AI40: 200
J41: 5 | K41: =I40/1000*J41*(1+$K$8) -> 1349.1709 | L41: 3 | M41: =$L$8*L41 -> 240 | N41: =SUM(K41:M41)*0.1 -> 159.21709 | O41: =SUM(K41+M41+N41) -> 1748.388 | P41: 500 | Q41: 5500 | R41: =(Q41-O41)/Q41 -> 0.68211127 | S41: =Q41/J41*1000 -> 1100000 | W41: =S41*(1-$W$8) -> 1100000 | X41: =S41*(1-$X$8) -> 990000 | Y41: =S41*(1-$Y$8) -> 935000 | Z41: =S41*(1-$Z$8) -> 880000 | AA41: =Q41*(1-$AA$8) -> 4400 | AB41: =(AA41-O41)/AA41 -> 0.60263909 | AC41: 용기포함 | AD41: - | AE41: 300 | AF41: 150 | AG41: 50 | AH41: 100 | AI41: 200
J42: 10 | K42: =I40/1000*J42*(1+$K$8) -> 2698.3418 | L42: 3 | M42: =$L$8*L42 -> 240 | N42: =SUM(K42:M42)*0.1 -> 294.13418 | O42: =SUM(K42+M42+N42) -> 3232.476 | P42: 500 | Q42: 8000 | R42: =(Q42-O42)/Q42 -> 0.5959405 | S42: =Q42/J42*1000 -> 800000 | W42: =S42*(1-$W$8) -> 800000 | X42: =S42*(1-$X$8) -> 720000 | Y42: =S42*(1-$Y$8) -> 680000 | Z42: =S42*(1-$Z$8) -> 640000 | AA42: =Q42*(1-$AA$8) -> 6400 | AB42: =(AA42-O42)/AA42 -> 0.49492563 | AC42: 용기포함 | AD42: - | AE42: 300 | AF42: 150 | AG42: 50 | AH42: 100 | AI42: 200
C43: TH SERIES (초고순도 / 저온저습) | D43: 1kg | E43: 256 | F43: 50 | G43: =E43*$G$8 -> 46.08 | H43: =SUM(E43:G43) -> 352.08 | I43: =H43*200 -> 70416 | J43: 3 | K43: =I43/1000*J43*(1+$K$8) -> 232.3728 | L43: 3 | M43: =$L$8*L43 -> 240 | N43: =SUM(K43:M43)*0.1 -> 47.53728 | O43: =SUM(K43+M43+N43) -> 519.91008 | P43: 500 | Q43: 1600 | R43: =(Q43-O43)/Q43 -> 0.6750562 | S43: =Q43/J43*1000 -> 533333.33 | U43: 300000 | W43: =S43*(1-$W$8) -> 533333.33 | X43: =S43*(1-$X$8) -> 480000 | Y43: =S43*(1-$Y$8) -> 453333.33 | Z43: =S43*(1-$Z$8) -> 426666.67 | AA43: =Q43*(1-$AA$8) -> 1280 | AB43: =(AA43-O43)/AA43 -> 0.59382025 | AC43: 용기포함 | AD43: - | AE43: 300 | AF43: 150 | AG43: 50 | AH43: 100 | AI43: 200
J44: 5 | K44: =I43/1000*J44*(1+$K$8) -> 387.288 | L44: 3 | M44: =$L$8*L44 -> 240 | N44: =SUM(K44:M44)*0.1 -> 63.0288 | O44: =SUM(K44+M44+N44) -> 690.3168 | P44: 500 | Q44: 2000 | R44: =(Q44-O44)/Q44 -> 0.6548416 | S44: =Q44/J44*1000 -> 400000 | W44: =S44*(1-$W$8) -> 400000 | X44: =S44*(1-$X$8) -> 360000 | Y44: =S44*(1-$Y$8) -> 340000 | Z44: =S44*(1-$Z$8) -> 320000 | AA44: =Q44*(1-$AA$8) -> 1600 | AB44: =(AA44-O44)/AA44 -> 0.568552 | AC44: 용기포함 | AD44: - | AE44: 300 | AF44: 150 | AG44: 50 | AH44: 100 | AI44: 200
J45: 10 | K45: =I43/1000*J45*(1+$K$8) -> 774.576 | L45: 3 | M45: =$L$8*L45 -> 240 | N45: =SUM(K45:M45)*0.1 -> 101.7576 | O45: =SUM(K45+M45+N45) -> 1116.3336 | P45: 500 | Q45: 3000 | R45: =(Q45-O45)/Q45 -> 0.6278888 | S45: =Q45/J45*1000 -> 300000 | W45: =S45*(1-$W$8) -> 300000 | X45: =S45*(1-$X$8) -> 270000 | Y45: =S45*(1-$Y$8) -> 255000 | Z45: =S45*(1-$Z$8) -> 240000 | AA45: =Q45*(1-$AA$8) -> 2400 | AB45: =(AA45-O45)/AA45 -> 0.534861 | AC45: 용기포함 | AD45: - | AE45: 300 | AF45: 150 | AG45: 50 | AH45: 100 | AI45: 200
C46: CM SERIES (초고순도 / 유연성) | D46: 1kg | E46: 323.5 | F46: 50 | G46: =E46*$G$8 -> 58.23 | H46: =SUM(E46:G46) -> 431.73 | I46: =H46*200 -> 86346 | J46: 3 | K46: =I46/1000*J46*(1+$K$8) -> 284.9418 | L46: 3 | M46: =$L$8*L46 -> 240 | N46: =SUM(K46:M46)*0.1 -> 52.79418 | O46: =SUM(K46+M46+N46) -> 577.73598 | P46: 500 | Q46: 1400 | R46: =(Q46-O46)/Q46 -> 0.58733144 | S46: =Q46/J46*1000 -> 466666.67 | U46: 280000 | W46: =S46*(1-$W$8) -> 466666.67 | X46: =S46*(1-$X$8) -> 420000 | Y46: =S46*(1-$Y$8) -> 396666.67 | Z46: =S46*(1-$Z$8) -> 373333.33 | AA46: =Q46*(1-$AA$8) -> 1120 | AB46: =(AA46-O46)/AA46 -> 0.4841643 | AC46: 용기포함 | AD46: - | AE46: 300 | AF46: 150 | AG46: 50 | AH46: 100 | AI46: 200
J47: 5 | K47: =I46/1000*J47*(1+$K$8) -> 474.903 | L47: 3 | M47: =$L$8*L47 -> 240 | N47: =SUM(K47:M47)*0.1 -> 71.7903 | O47: =SUM(K47+M47+N47) -> 786.6933 | P47: 500 | Q47: 1800 | R47: =(Q47-O47)/Q47 -> 0.56294817 | S47: =Q47/J47*1000 -> 360000 | W47: =S47*(1-$W$8) -> 360000 | X47: =S47*(1-$X$8) -> 324000 | Y47: =S47*(1-$Y$8) -> 306000 | Z47: =S47*(1-$Z$8) -> 288000 | AA47: =Q47*(1-$AA$8) -> 1440 | AB47: =(AA47-O47)/AA47 -> 0.45368521 | AC47: 용기포함 | AD47: - | AE47: 300 | AF47: 150 | AG47: 50 | AH47: 100 | AI47: 200
J48: 10 | K48: =I46/1000*J48*(1+$K$8) -> 949.806 | L48: 3 | M48: =$L$8*L48 -> 240 | N48: =SUM(K48:M48)*0.1 -> 119.2806 | O48: =SUM(K48+M48+N48) -> 1309.0866 | P48: 500 | Q48: 2800 | R48: =(Q48-O48)/Q48 -> 0.53246907 | S48: =Q48/J48*1000 -> 280000 | W48: =S48*(1-$W$8) -> 280000 | X48: =S48*(1-$X$8) -> 252000 | Y48: =S48*(1-$Y$8) -> 238000 | Z48: =S48*(1-$Z$8) -> 224000 | AA48: =Q48*(1-$AA$8) -> 2240 | AB48: =(AA48-O48)/AA48 -> 0.41558634 | AC48: 용기포함 | AD48: - | AE48: 300 | AF48: 150 | AG48: 50 | AH48: 100 | AI48: 200
C49: S SERIES (고순도 / 빠른경화) | D49: 1kg | E49: 220 | F49: 50 | G49: =E49*$G$8 -> 39.6 | H49: =SUM(E49:G49) -> 309.6 | I49: =H49*200 -> 61920 | J49: 3 | K49: =I49/1000*J49*(1+$K$8) -> 204.336 | L49: 3 | M49: =$L$8*L49 -> 240 | N49: =SUM(K49:M49)*0.1 -> 44.7336 | O49: =SUM(K49+M49+N49) -> 489.0696 | P49: 500 | Q49: 1200 | R49: =(Q49-O49)/Q49 -> 0.592442 | S49: =Q49/J49*1000 -> 400000 | U49: 240000 | W49: =S49*(1-$W$8) -> 400000 | X49: =S49*(1-$X$8) -> 360000 | Y49: =S49*(1-$Y$8) -> 340000 | Z49: =S49*(1-$Z$8) -> 320000 | AA49: =Q49*(1-$AA$8) -> 960 | AB49: =(AA49-O49)/AA49 -> 0.4905525 | AC49: 용기포함 | AD49: - | AE49: 300 | AF49: 150 | AG49: 50 | AH49: 100 | AI49: 200
J50: 5 | K50: =I49/1000*J50*(1+$K$8) -> 340.56 | L50: 3 | M50: =$L$8*L50 -> 240 | N50: =SUM(K50:M50)*0.1 -> 58.356 | O50: =SUM(K50+M50+N50) -> 638.916 | P50: 500 | Q50: 1600 | R50: =(Q50-O50)/Q50 -> 0.6006775 | S50: =Q50/J50*1000 -> 320000 | W50: =S50*(1-$W$8) -> 320000 | X50: =S50*(1-$X$8) -> 288000 | Y50: =S50*(1-$Y$8) -> 272000 | Z50: =S50*(1-$Z$8) -> 256000 | AA50: =Q50*(1-$AA$8) -> 1280 | AB50: =(AA50-O50)/AA50 -> 0.50084688 | AC50: 용기포함 | AD50: - | AE50: 300 | AF50: 150 | AG50: 50 | AH50: 100 | AI50: 200
J51: 10 | K51: =I49/1000*J51*(1+$K$8) -> 681.12 | L51: 3 | M51: =$L$8*L51 -> 240 | N51: =SUM(K51:M51)*0.1 -> 92.412 | O51: =SUM(K51+M51+N51) -> 1013.532 | P51: 500 | Q51: 2600 | R51: =(Q51-O51)/Q51 -> 0.61018 | S51: =Q51/J51*1000 -> 260000 | W51: =S51*(1-$W$8) -> 260000 | X51: =S51*(1-$X$8) -> 234000 | Y51: =S51*(1-$Y$8) -> 221000 | Z51: =S51*(1-$Z$8) -> 208000 | AA51: =Q51*(1-$AA$8) -> 2080 | AB51: =(AA51-O51)/AA51 -> 0.512725 | AC51: 용기포함 | AD51: - | AE51: 300 | AF51: 150 | AG51: 50 | AH51: 100 | AI51: 200
...
